#VRML_SIM R2023a utf8

EXTERNPROTO "https://raw.githubusercontent.com/cyberbotics/webots/R2023a/projects/objects/backgrounds/protos/TexturedBackground.proto"
EXTERNPROTO "https://raw.githubusercontent.com/cyberbotics/webots/R2023a/projects/objects/backgrounds/protos/TexturedBackgroundLight.proto"
EXTERNPROTO "https://raw.githubusercontent.com/cyberbotics/webots/R2023a/projects/objects/floors/protos/Floor.proto"

WorldInfo {
  contactProperties [
    ContactProperties {
      material2 "dumbbell"
      coulombFriction [
        0
      ]
    }
  ]
}
Viewpoint {
  orientation 0.4596364758242076 -0.03479693843044991 -0.8874251986324089 3.275750556175865
  position 3.688272040364694 -0.09044511983357688 5.290756634171268
}
TexturedBackground {
}
TexturedBackgroundLight {
}
Floor {
  size 4 4
  appearance PBRAppearance {
    baseColorMap ImageTexture {
      url [
        "Grass_Sprite.png"
      ]
    }
    roughness 1
    metalness 0
  }
}
Robot {
  translation 0.10996805173136215 -1.7074898345295667e-07 0.03959752629435106
  rotation -0.0019170312462347744 -0.9999968283343318 -0.001633497008807273 0.0022818433056824815
  children [
    HingeJoint {
      jointParameters HingeJointParameters {
        position 9.032038639064568e-08
        axis 0 1 0
        anchor -0.04 0 0.03
      }
      device [
        RotationalMotor {
          name "brazo"
        }
      ]
      endPoint Solid {
        translation -0.029999996387049102 0 0.07000149909679597
        rotation 0 1 0 8.940696716308595e-08
        children [
          HingeJoint {
            jointParameters HingeJointParameters {
              position -1.5316134877337812e-09
              axis 0 1 0
              anchor 0 0 0.04
            }
            device [
              RotationalMotor {
                name "brazo_agarre"
              }
            ]
            endPoint Solid {
              translation 4.8005830760274314e-06 3.220740111300017e-07 0.06999669191592135
              rotation -0.0002053618541507026 0.9999999786217285 -2.414645364477637e-05 0.00013307953682042454
              children [
                DEF agarre Group {
                  children [
                    Transform {
                      translation -0.0150004 0.0486603 0.03
                      rotation 0 0 1 1.5708
                      children [
                        Shape {
                          appearance DEF VERDE Appearance {
                            material Material {
                              diffuseColor 0.0627451 0.8 0.00784314
                            }
                          }
                          geometry Box {
                            size 0.01 0.02 0.02
                          }
                        }
                      ]
                    }
                    Transform {
                      translation -0.0150001 -0.0513397 0.03
                      rotation 0 0 1 1.5708
                      children [
                        Shape {
                          appearance DEF VERDE Appearance {
                            material Material {
                              diffuseColor 0.0627451 0.8 0.00784314
                            }
                          }
                          geometry Box {
                            size 0.01 0.02 0.02
                          }
                        }
                      ]
                    }
                    Transform {
                      translation 0 0 0.03
                      children [
                        Shape {
                          appearance DEF VERDE Appearance {
                            material Material {
                              diffuseColor 0.0627451 0.8 0.00784314
                            }
                          }
                          geometry Box {
                            size 0.01 0.1 0.02
                          }
                        }
                      ]
                    }
                    Shape {
                      appearance DEF VERDE Appearance {
                        material Material {
                          diffuseColor 0.0627451 0.8 0.00784314
                        }
                      }
                      geometry Box {
                        size 0.01 0.01 0.06
                      }
                    }
                  ]
                }
              ]
              name "solid(1)"
              boundingObject USE agarre
              physics Physics {
              }
            }
          }
          DEF WHEEL1 Shape {
            appearance DEF VERDE Appearance {
              material Material {
                diffuseColor 0.0627451 0.8 0.00784314
              }
            }
            geometry Box {
              size 0.01 0.01 0.08
            }
          }
        ]
        name "solid(3)"
        boundingObject USE WHEEL1
        physics Physics {
        }
      }
    }
    GPS {
    }
    DistanceSensor {
      translation 0.0473204 0 0.0273204
      rotation 0 1 0 -0.3927003061004253
      children [
        DEF sensor Shape {
          appearance PBRAppearance {
            baseColor 0 0 0.498039
            roughness 1
            metalness 0
          }
          geometry Box {
            size 0.01 0.01 0.01
          }
        }
      ]
      name "sensor_altura"
      boundingObject USE sensor
      lookupTable [
        0 0 0
        0.2 1000 0
      ]
    }
    DistanceSensor {
      translation 0.0477666 -0.014776 0
      rotation 0 0 1 -0.3
      children [
        DEF sensor Shape {
          appearance Appearance {
            material Material {
              diffuseColor 0 0 0.498039
            }
          }
          geometry Box {
            size 0.01 0.01 0.01
          }
        }
      ]
      name "sensor_der"
      boundingObject USE sensor
      lookupTable [
        0 0 0
        0.2 1000 0
      ]
    }
    DistanceSensor {
      translation 0.0477666 0.014776 0
      rotation 0 0 1 0.3
      children [
        DEF Sensor Shape {
          appearance Appearance {
            material Material {
              diffuseColor 0 0 0.498039
            }
          }
          geometry Box {
            size 0.01 0.01 0.01
          }
        }
      ]
      name "sensor_izq"
      boundingObject USE Sensor
      lookupTable [
        0 0 0
        0.2 1000 0
      ]
      aperture 0.2
      gaussianWidth 3
    }
    DEF CUERPO_BOT Shape {
      appearance Appearance {
        material Material {
          diffuseColor 0.8 0 0
        }
      }
      geometry Box {
        size 0.1 0.1 0.07
      }
    }
    HingeJoint {
      jointParameters HingeJointParameters {
        position 2.7839998051977446
        axis 0 1 0
        anchor 0 0.06 0
      }
      device [
        RotationalMotor {
          name "wheel1"
        }
      ]
      endPoint Solid {
        translation 1.0900350005461507e-05 0.059999999088792 2.485156710481675e-06
        rotation 0.12748818753946656 0.7013355596845227 -0.7013381458040757 2.8879852781052273
        children [
          DEF WHEEL1 Shape {
            appearance DEF VERDE Appearance {
              material Material {
                diffuseColor 0.0627451 0.8 0.00784314
              }
            }
            geometry DEF RUEDA Cylinder {
              height 0.02
              radius 0.04
            }
          }
        ]
        name "solid(1)"
        boundingObject USE WHEEL1
        physics Physics {
        }
      }
    }
    HingeJoint {
      jointParameters HingeJointParameters {
        position 2.7839997959369582
        axis 0 1 0
        anchor 0 -0.06 0
      }
      device [
        RotationalMotor {
          name "wheel2"
        }
      ]
      endPoint Solid {
        translation 1.1178013759126461e-05 -0.06 1.7772796018576949e-06
        rotation -0.12729152358771 -0.7013534204189562 0.7013560063828856 3.3948129858172704
        children [
          DEF WHEEL2 Shape {
            appearance USE VERDE
            geometry USE RUEDA
          }
        ]
        name "solid(2)"
        boundingObject USE WHEEL2
        physics Physics {
        }
      }
    }
  ]
  boundingObject Shape {
    geometry Box {
      size 0.1 0.1 0.079
    }
  }
  physics Physics {
  }
  controller "4wheel_controller"
}
Solid {
  translation -1.96 0 0.24
  children [
    DEF PARED Shape {
      appearance DEF AZUL PBRAppearance {
        baseColor 0 0 0.498039
        roughness 1
        metalness 0
      }
      geometry DEF PARED Box {
        size 0.1 4 0.5
      }
    }
  ]
  name "pared1"
  boundingObject USE PARED
}
Solid {
  translation 1.96 0 0.24
  children [
    DEF PARED Shape {
      appearance DEF AZUL PBRAppearance {
        baseColor 0 0 0.498039
        roughness 1
        metalness 0
      }
      geometry DEF PARED Box {
        size 0.1 4 0.5
      }
    }
  ]
  name "pared2"
  boundingObject USE PARED
}
Solid {
  translation -6.74634e-14 -2.01 0.24
  rotation 0 0 1 1.5708
  children [
    DEF PARED Shape {
      appearance DEF AZUL PBRAppearance {
        baseColor 0 0 0.498039
        roughness 1
        metalness 0
      }
      geometry DEF PARED Box {
        size 0.1 4 0.5
      }
    }
  ]
  name "pared3"
  boundingObject USE PARED
}
Solid {
  translation 0.01 1.98 0.24
  rotation 0 0 1 -1.5707953071795862
  children [
    DEF PARED Shape {
      appearance DEF AZUL PBRAppearance {
        baseColor 0 0 0.498039
        roughness 1
        metalness 0
      }
      geometry DEF PARED Box {
        size 0.1 4 0.5
      }
    }
  ]
  name "pared4"
  boundingObject USE PARED
}
Solid {
  translation 0 1.08 0.2
  children [
    Group {
      children [
        Transform {
          translation 0 0 0.3
          children [
            Shape {
              appearance DEF VERDE PBRAppearance {
                baseColor 0.0352941 0.482353 0.0352941
                roughness 1
                metalness 0
              }
              geometry DEF HOJAS Cone {
                bottomRadius 0.16
                height 0.2
              }
            }
          ]
        }
        Transform {
          translation 0 0 0.2
          children [
            Shape {
              appearance DEF VERDE PBRAppearance {
                baseColor 0.0352941 0.482353 0.0352941
                roughness 1
                metalness 0
              }
              geometry DEF HOJAS Cone {
                bottomRadius 0.16
                height 0.2
              }
            }
          ]
        }
        Transform {
          translation 0 0 0.1
          children [
            Shape {
              appearance DEF VERDE PBRAppearance {
                baseColor 0.0352941 0.482353 0.0352941
                roughness 1
                metalness 0
              }
              geometry DEF HOJAS Cone {
                bottomRadius 0.16
                height 0.2
              }
            }
          ]
        }
        DEF TRONCO Shape {
          appearance PBRAppearance {
            baseColor 0.341176 0.207843 0.0235294
            roughness 1
            metalness 0
          }
          geometry Cylinder {
            height 0.4
            radius 0.05
          }
        }
      ]
    }
  ]
  name "arbol1"
  boundingObject USE TRONCO
}
Solid {
  translation 0.41 -0.05999999999999999 0.024903891496521894
  rotation 0.6626387917863038 -0.7454686407595857 -0.07201622917123052 2.83894370397396e-16
  children [
    DEF objetivo Shape {
      appearance PBRAppearance {
        baseColor 0 1 0
        metalness 0
      }
      geometry Box {
        size 0.07 0.07 0.05
      }
    }
  ]
  boundingObject USE objetivo
  physics Physics {
  }
}
Solid {
  translation -1 0 0
  children [
    Shape {
      geometry Box {
        size 0.5 0.5 0.01
      }
    }
  ]
  name "plataforma"
}
Solid {
  translation 0.41 -0.91 0.0249039
  rotation 0.6626387917863038 -0.7454686407595857 -0.07201622917123052 2.83894370397396e-16
  children [
    DEF objetivo Shape {
      appearance PBRAppearance {
        baseColor 0 1 0
        metalness 0
      }
      geometry Box {
        size 0.07 0.07 0.05
      }
    }
  ]
  name "solid(1)"
  boundingObject USE objetivo
  physics Physics {
  }
}
Solid {
  translation -0.21 -0.56 0.0249039
  rotation 0.6626387917863038 -0.7454686407595857 -0.07201622917123052 2.83894370397396e-16
  children [
    DEF objetivo Shape {
      appearance PBRAppearance {
        baseColor 0 1 0
        metalness 0
      }
      geometry Box {
        size 0.07 0.07 0.05
      }
    }
  ]
  name "solid(2)"
  boundingObject USE objetivo
  physics Physics {
  }
}
Solid {
  translation 0.41 0.72 0.0249039
  rotation 0.6626387917863038 -0.7454686407595857 -0.07201622917123052 2.83894370397396e-16
  children [
    DEF objetivo Shape {
      appearance PBRAppearance {
        baseColor 0 1 0
        metalness 0
      }
      geometry Box {
        size 0.07 0.07 0.05
      }
    }
  ]
  name "solid(3)"
  boundingObject USE objetivo
  physics Physics {
  }
}
Solid {
  translation 1.09 -0.06 0.0249039
  rotation 0.6626387917863038 -0.7454686407595857 -0.07201622917123052 2.83894370397396e-16
  children [
    DEF objetivo Shape {
      appearance PBRAppearance {
        baseColor 0 1 0
        metalness 0
      }
      geometry Box {
        size 0.07 0.07 0.05
      }
    }
  ]
  name "solid(4)"
  boundingObject USE objetivo
  physics Physics {
  }
}
Solid {
  translation 0.9 0.41 0.0249039
  rotation 0.6626387917863038 -0.7454686407595857 -0.07201622917123052 2.83894370397396e-16
  children [
    DEF objetivo Shape {
      appearance PBRAppearance {
        baseColor 0 1 0
        metalness 0
      }
      geometry Box {
        size 0.07 0.07 0.05
      }
    }
  ]
  name "solid(5)"
  boundingObject USE objetivo
  physics Physics {
  }
}
